Utilizar `throw` en lugar de hacer `return` en cada comprobación dentro de tu función tiene ventajas y desventajas. A continuación, te explico ambos enfoques, sus implicaciones, y cuándo podría ser mejor uno sobre el otro.

### **Ventajas de usar `throw`:**

1. **Centralización del manejo de errores**:

   - Usar `throw` te permite centralizar el manejo de los errores. En lugar de manejar el error en cada parte del flujo con `return`, puedes capturar todos los errores en el bloque `catch` y manejar la respuesta HTTP en un solo lugar.
   - Esto hace que el código sea más limpio, ya que no tienes que lidiar con múltiples retornos y mensajes de error dispersos a lo largo del código.

2. **Reutilización del código de manejo de errores**:
   - Si cada vez que ocurre un error quieres realizar acciones comunes (como logging o una respuesta estandarizada), `throw` permite tener una única sección en el bloque `catch` para manejar todas las excepciones.
3. **Estructura de código más clara**:
   - El flujo de control puede ser más fácil de seguir, ya que no tienes múltiples puntos de salida dentro de la función. Al lanzar excepciones, mantienes un solo lugar donde se maneja la finalización de la función, lo que a veces facilita la lectura del código.
4. **Facilidad de propagación**:
   - En sistemas donde las excepciones deben ser propagadas a niveles superiores de la aplicación, lanzar un `throw` permite escalar los errores a otros manejadores de excepciones globales, mientras que el `return` corta el flujo de la función sin propagación.

### **Desventajas de usar `throw`:**

1. **Sobrecarga en el manejo de excepciones**:

   - El manejo de excepciones (con `throw`) es costoso en términos de rendimiento comparado con simples verificaciones y retornos. Si tu código espera tener errores frecuentemente, el enfoque de `throw` puede ser menos eficiente que devolver un error directamente con `return`.
   - `throw` debería reservarse para situaciones excepcionales, mientras que los flujos controlados y esperados de errores se pueden manejar mejor con `return`.

2. **Pérdida de control fino en el flujo**:

   - Al utilizar `throw`, pierdes la capacidad de responder a errores específicos de inmediato. Esto puede ser desventajoso si quieres reaccionar de diferentes maneras dependiendo del tipo de error (por ejemplo, si hay un error al obtener el token o al consultar la base de datos).
   - Si manejas todo en un solo `catch`, corres el riesgo de hacer un manejo genérico de errores, cuando tal vez ciertos errores requieran una respuesta más específica.

3. **Menos explícito para errores previsibles**:
   - Los errores manejados con `return` pueden ser más explícitos para casos donde los problemas son esperados (por ejemplo, un código de autorización inválido). Usar `throw` podría no ser tan adecuado para estos casos previsibles, ya que se usa más comúnmente para situaciones excepcionales.

### **Propuesta de usar `throw`**:

Si decides usar `throw`, el código podría verse así:

```javascript
function handleAuthGitHubCallback(db, secretKey) {
  return async function (req, res) {
    try {
      const gitHubCode = req.query.code;
      if (!gitHubCode) {
        throw new Error("No authorization code received");
      }

      // Solicita el token de acceso a GitHub
      const ghResponse = await fetch(gitHubEP.ACCESS_TOKEN, {
        method: "POST",
        headers: {
          "Content-Type": "application/json",
          Accept: "application/json",
        },
        body: JSON.stringify({
          client_id: clientID,
          client_secret: clientSecret,
          code: gitHubCode,
          redirect_uri: redirectURI,
        }),
      });

      if (!ghResponse.ok) {
        throw new Error(`GitHub error: ${ghResponse.statusText}`);
      }

      const { access_token: ghAccessToken } = await ghResponse.json();
      if (!ghAccessToken) {
        throw new Error("Error obtaining access token from GitHub");
      }

      // Solicita los datos del usuario de GitHub
      const ghUserResponse = await fetch(gitHubEP.USER, {
        method: "GET",
        headers: {
          Authorization: `Bearer ${ghAccessToken}`,
        },
      });

      if (!ghUserResponse.ok) {
        throw new Error(
          `Error fetching GitHub user: ${ghUserResponse.statusText}`
        );
      }

      const ghUserData = await ghUserResponse.json();
      if (!ghUserData || !ghUserData.email) {
        throw new Error("Invalid GitHub user data");
      }

      // Verifica si el usuario existe en la base de datos
      let userInDB = await getUserByEmail(db, ghUserData.email);
      if (!userInDB) {
        const timestamp = Date.now();
        const id = await insertUser(
          db,
          ghUserData.email,
          hashPassword(timestamp.toString())
        );
        req.session.user = { id: id, email: ghUserData.email };
      } else {
        req.session.user = { id: userInDB.id, email: userInDB.email };
      }

      // Genera el token JWT
      const jwtToken = await generateToken(
        { user: req.session.user },
        secretKey
      );
      res.cookie("jwtToken", jwtToken, {
        httpOnly: true,
        secure: false,
      });

      let returnTo = req.session.returnTo || "/";
      delete req.session.returnTo;
      res.redirect(returnTo);
    } catch (error) {
      console.error("Error during GitHub authentication", error.message);
      res.status(500).send(error.message || "Authentication failed");
    }
  };
}
```

### **Diferencias clave:**

- En lugar de realizar `return res.status(...)` después de cada validación o comprobación, se lanza un `throw new Error(...)` que será capturado por el bloque `catch`.
- El bloque `catch` ahora se encarga de manejar cualquier error que ocurra en todo el flujo, proporcionando una respuesta centralizada y limpia.

### **Conclusión**:

- **Usar `throw`**: Es útil cuando deseas centralizar el manejo de errores y tratar todos los fallos de manera uniforme. También es ventajoso si tienes muchas situaciones "excepcionales" que ameritan romper el flujo de ejecución y capturarlas globalmente.
- **Usar `return`**: Es más adecuado para flujos de control más predecibles y donde esperas manejar errores en el lugar donde ocurren, devolviendo respuestas específicas de inmediato sin necesidad de pasar por un bloque `catch`.

Ambos enfoques son válidos, pero dependen de si prefieres un manejo de errores más centralizado y controlado (`throw`) o un manejo específico y localizado (`return`).

## **Código anterior con `return`**:

```javascript
function handleAuthGitHubCallback(db, secretKey) {
  return async function (req, res) {
    const gitHubCode = req.query.code;
    if (!gitHubCode) {
      return res.status(400).send("No authorization code received");
    }

    try {
      // Solicita el token de acceso a GitHub
      const ghResponse = await fetch(gitHubEP.ACCESS_TOKEN, {
        method: "POST",
        headers: {
          "Content-Type": "application/json",
          Accept: "application/json",
        },
        body: JSON.stringify({
          client_id: clientID,
          client_secret: clientSecret,
          code: gitHubCode,
          redirect_uri: redirectURI,
        }),
      });

      if (!ghResponse.ok) {
        console.error(
          `Error from GitHub: ${ghResponse.status} ${ghResponse.statusText}`
        );
        return res.status(502).send("Error communicating with GitHub");
      }

      const { access_token: ghAccessToken } = await ghResponse.json();
      if (!ghAccessToken) {
        console.error("GitHub access token missing");
        return res.status(400).send("Error obtaining access token from GitHub");
      }

      // Solicita los datos del usuario de GitHub
      const ghUserResponse = await fetch(gitHubEP.USER, {
        method: "GET",
        headers: {
          Authorization: `Bearer ${ghAccessToken}`,
        },
      });

      if (!ghUserResponse.ok) {
        console.error(
          `Error fetching GitHub user: ${ghUserResponse.status} ${ghUserResponse.statusText}`
        );
        return res.status(502).send("Error fetching user data from GitHub");
      }

      const ghUserData = await ghUserResponse.json();
      if (!ghUserData || !ghUserData.email) {
        console.error("GitHub user data invalid or missing email");
        return res.status(400).send("Invalid GitHub user data");
      }

      // Verifica si el usuario existe en la base de datos
      let userInDB = await getUserByEmail(db, ghUserData.email);
      if (!userInDB) {
        try {
          const timestamp = Date.now();
          const id = await insertUser(
            db,
            ghUserData.email,
            hashPassword(timestamp.toString())
          );
          req.session.user = { id: id, email: ghUserData.email };
        } catch (error) {
          console.error("Error registering user in DB", error);
          return res.status(500).json({ error: "Error registering user" });
        }
      } else {
        req.session.user = { id: userInDB.id, email: userInDB.email };
      }

      // Genera el token JWT
      try {
        const jwtToken = await generateToken(
          { user: req.session.user },
          secretKey
        );
        res.cookie("jwtToken", jwtToken, {
          httpOnly: true, // Evita que el frontend acceda a esta cookie
          secure: false, // TODO: Cambiar a true en producción con HTTPS
        });
      } catch (error) {
        console.error("Error generating JWT token", error);
        return res
          .status(500)
          .json({ error: "Error generating authentication token" });
      }

      // Redirecciona al usuario
      let returnTo = req.session.returnTo || "/";
      delete req.session.returnTo;
      return res.redirect(returnTo);
    } catch (error) {
      console.error("Unexpected error during GitHub authentication", error);
      return res
        .status(500)
        .send("An unexpected error occurred during authentication");
    }
  };
}
```
